Workbook

Sheet Dependencias
A1: Semestre | B1: Clave (id en Prolog) | C1: Materia | D1: Prerrequisito 1 | E1: Prerrequisito 2 | F1: Prerrequisito 3 | G1: No. de prerrequisitos | H1: Materias que desbloquea
A2: 1 | B2: fundamentos_programacion | C2: Fundamentos de Programación | G2: =COUNTA(D2:F2) -> 0 | H2: =COUNTIF($D$2:$F$46,C2) -> 1
A3: 1 | B3: matematicas_discretas | C3: Matemáticas Discretas | G3: =COUNTA(D3:F3) -> 0 | H3: =COUNTIF($D$2:$F$46,C3) -> 2
A4: 1 | B4: calculo | C4: Cálculo | G4: =COUNTA(D4:F4) -> 0 | H4: =COUNTIF($D$2:$F$46,C4) -> 1
A5: 1 | B5: comunicacion_oral_escrita | C5: Comunicación Oral y Escrita | G5: =COUNTA(D5:F5) -> 0 | H5: =COUNTIF($D$2:$F$46,C5) -> 0
A6: 1 | B6: mecanica_electromagnetismo | C6: Mecánica y Electromagnetismo | G6: =COUNTA(D6:F6) -> 0 | H6: =COUNTIF($D$2:$F$46,C6) -> 0
A7: 1 | B7: fundamentos_economicos | C7: Fundamentos Económicos | G7: =COUNTA(D7:F7) -> 0 | H7: =COUNTIF($D$2:$F$46,C7) -> 1
A8: 2 | B8: algoritmos_estructuras_datos | C8: Algoritmos y Estructuras de Datos | D8: Fundamentos de Programación | G8: =COUNTA(D8:F8) -> 1 | H8: =COUNTIF($D$2:$F$46,C8) -> 3
A9: 2 | B9: fundamentos_diseno_digital | C9: Fundamentos de Diseño Digital | G9: =COUNTA(D9:F9) -> 0 | H9: =COUNTIF($D$2:$F$46,C9) -> 1
A10: 2 | B10: calculo_multivariable | C10: Cálculo Multivariable | D10: Cálculo | G10: =COUNTA(D10:F10) -> 1 | H10: =COUNTIF($D$2:$F$46,C10) -> 2
A11: 2 | B11: ingenieria_etica_sociedad | C11: Ingeniería, Ética y Sociedad | G11: =COUNTA(D11:F11) -> 0 | H11: =COUNTIF($D$2:$F$46,C11) -> 0
A12: 2 | B12: algebra_lineal | C12: Álgebra Lineal | G12: =COUNTA(D12:F12) -> 0 | H12: =COUNTIF($D$2:$F$46,C12) -> 2
A13: 2 | B13: finanzas_empresariales | C13: Finanzas Empresariales | D13: Fundamentos Económicos | G13: =COUNTA(D13:F13) -> 1 | H13: =COUNTIF($D$2:$F$46,C13) -> 2
A14: 3 | B14: analisis_diseno_algoritmos | C14: Análisis y Diseño de Algoritmos | D14: Algoritmos y Estructuras de Datos | E14: Matemáticas Discretas | G14: =COUNTA(D14:F14) -> 2 | H14: =COUNTIF($D$2:$F$46,C14) -> 3
A15: 3 | B15: paradigmas_programacion | C15: Paradigmas de Programación | D15: Algoritmos y Estructuras de Datos | G15: =COUNTA(D15:F15) -> 1 | H15: =COUNTIF($D$2:$F$46,C15) -> 1
A16: 3 | B16: ecuaciones_diferenciales | C16: Ecuaciones Diferenciales | D16: Cálculo Multivariable | G16: =COUNTA(D16:F16) -> 1 | H16: =COUNTIF($D$2:$F$46,C16) -> 2
A17: 3 | B17: bases_datos | C17: Bases de Datos | D17: Algoritmos y Estructuras de Datos | G17: =COUNTA(D17:F17) -> 1 | H17: =COUNTIF($D$2:$F$46,C17) -> 2
A18: 3 | B18: diseno_sistemas_digitales | C18: Diseño de Sistemas Digitales | D18: Fundamentos de Diseño Digital | G18: =COUNTA(D18:F18) -> 1 | H18: =COUNTIF($D$2:$F$46,C18) -> 0
A19: 3 | B19: liderazgo_personal | C19: Liderazgo Personal | G19: =COUNTA(D19:F19) -> 0 | H19: =COUNTIF($D$2:$F$46,C19) -> 1
A20: 4 | B20: fundamentos_ia | C20: Fundamentos de Inteligencia Artificial | D20: Paradigmas de Programación | E20: Matemáticas Discretas | G20: =COUNTA(D20:F20) -> 2 | H20: =COUNTIF($D$2:$F$46,C20) -> 9
A21: 4 | B21: probabilidad_estadistica | C21: Probabilidad y Estadística | D21: Cálculo Multivariable | G21: =COUNTA(D21:F21) -> 1 | H21: =COUNTIF($D$2:$F$46,C21) -> 1
A22: 4 | B22: matematicas_avanzadas | C22: Matemáticas Avanzadas para la Ingeniería | D22: Ecuaciones Diferenciales | E22: Álgebra Lineal | G22: =COUNTA(D22:F22) -> 2 | H22: =COUNTIF($D$2:$F$46,C22) -> 0
A23: 4 | B23: tecnologias_web | C23: Tecnologías para el Desarrollo de Aplicaciones Web | D23: Bases de Datos | G23: =COUNTA(D23:F23) -> 1 | H23: =COUNTIF($D$2:$F$46,C23) -> 0
A24: 4 | B24: analisis_diseno_sistemas | C24: Análisis y Diseño de Sistemas | D24: Bases de Datos | G24: =COUNTA(D24:F24) -> 1 | H24: =COUNTIF($D$2:$F$46,C24) -> 1
A25: 4 | B25: procesamiento_digital_senales | C25: Procesamiento Digital de Señales | D25: Ecuaciones Diferenciales | E25: Álgebra Lineal | G25: =COUNTA(D25:F25) -> 2 | H25: =COUNTIF($D$2:$F$46,C25) -> 2
A26: 5 | B26: aprendizaje_maquina | C26: Aprendizaje de Máquina | D26: Fundamentos de Inteligencia Artificial | E26: Probabilidad y Estadística | G26: =COUNTA(D26:F26) -> 2 | H26: =COUNTIF($D$2:$F$46,C26) -> 2
A27: 5 | B27: vision_artificial | C27: Visión Artificial | D27: Fundamentos de Inteligencia Artificial | E27: Procesamiento Digital de Señales | G27: =COUNTA(D27:F27) -> 2 | H27: =COUNTIF($D$2:$F$46,C27) -> 0
A28: 5 | B28: teoria_computacion | C28: Teoría de la Computación | D28: Análisis y Diseño de Algoritmos | G28: =COUNTA(D28:F28) -> 1 | H28: =COUNTIF($D$2:$F$46,C28) -> 0
A29: 5 | B29: procesamiento_senales | C29: Procesamiento de Señales | D29: Procesamiento Digital de Señales | G29: =COUNTA(D29:F29) -> 1 | H29: =COUNTIF($D$2:$F$46,C29) -> 1
A30: 5 | B30: algoritmos_bioinspirados | C30: Algoritmos Bioinspirados | D30: Fundamentos de Inteligencia Artificial | E30: Análisis y Diseño de Algoritmos | G30: =COUNTA(D30:F30) -> 2 | H30: =COUNTIF($D$2:$F$46,C30) -> 0
A31: 5 | B31: tecnologias_lenguaje_natural | C31: Tecnologías de Lenguaje Natural | D31: Fundamentos de Inteligencia Artificial | G31: =COUNTA(D31:F31) -> 1 | H31: =COUNTIF($D$2:$F$46,C31) -> 0
A32: 6 | B32: computo_paralelo | C32: Cómputo Paralelo | D32: Análisis y Diseño de Algoritmos | G32: =COUNTA(D32:F32) -> 1 | H32: =COUNTIF($D$2:$F$46,C32) -> 0
A33: 6 | B33: redes_neuronales | C33: Redes Neuronales y Aprendizaje Profundo | D33: Aprendizaje de Máquina | G33: =COUNTA(D33:F33) -> 1 | H33: =COUNTIF($D$2:$F$46,C33) -> 0
A34: 6 | B34: ingenieria_software_si | C34: Ingeniería de Software para Sistemas Inteligentes | D34: Análisis y Diseño de Sistemas | E34: Fundamentos de Inteligencia Artificial | G34: =COUNTA(D34:F34) -> 2 | H34: =COUNTIF($D$2:$F$46,C34) -> 1
A35: 6 | B35: optativa_a | C35: Optativa A | D35: Fundamentos de Inteligencia Artificial | G35: =COUNTA(D35:F35) -> 1 | H35: =COUNTIF($D$2:$F$46,C35) -> 0
A36: 6 | B36: optativa_b | C36: Optativa B | D36: Fundamentos de Inteligencia Artificial | G36: =COUNTA(D36:F36) -> 1 | H36: =COUNTIF($D$2:$F$46,C36) -> 0
A37: 6 | B37: metodologia_investigacion | C37: Metodología de la Investigación y Divulgación Científica | G37: =COUNTA(D37:F37) -> 0 | H37: =COUNTIF($D$2:$F$46,C37) -> 1
A38: 7 | B38: reconocimiento_voz | C38: Reconocimiento de Voz | D38: Procesamiento de Señales | E38: Aprendizaje de Máquina | G38: =COUNTA(D38:F38) -> 2 | H38: =COUNTIF($D$2:$F$46,C38) -> 0
A39: 7 | B39: trabajo_terminal_1 | C39: Trabajo Terminal I | D39: Ingeniería de Software para Sistemas Inteligentes | E39: Metodología de la Investigación y Divulgación Científica | G39: =COUNTA(D39:F39) -> 2 | H39: =COUNTIF($D$2:$F$46,C39) -> 2
A40: 7 | B40: formulacion_proyectos | C40: Formulación y Evaluación de Proyectos Informáticos | D40: Finanzas Empresariales | G40: =COUNTA(D40:F40) -> 1 | H40: =COUNTIF($D$2:$F$46,C40) -> 0
...

Sheet Relaciones
A1: Materia (depende de) | B1: Sem. materia | C1: Prerrequisito | D1: Sem. prerrequisito | E1: Diferencia de semestres | F1: ¿Prerrequisito de semestre anterior?
A2: Algoritmos y Estructuras de Datos | B2: 2 | C2: Fundamentos de Programación | D2: 1 | E2: =B2-D2 -> 1 | F2: =IF(D2<B2,"Sí","NO - revisar") -> Sí
A3: Cálculo Multivariable | B3: 2 | C3: Cálculo | D3: 1 | E3: =B3-D3 -> 1 | F3: =IF(D3<B3,"Sí","NO - revisar") -> Sí
A4: Finanzas Empresariales | B4: 2 | C4: Fundamentos Económicos | D4: 1 | E4: =B4-D4 -> 1 | F4: =IF(D4<B4,"Sí","NO - revisar") -> Sí
A5: Análisis y Diseño de Algoritmos | B5: 3 | C5: Algoritmos y Estructuras de Datos | D5: 2 | E5: =B5-D5 -> 1 | F5: =IF(D5<B5,"Sí","NO - revisar") -> Sí
A6: Análisis y Diseño de Algoritmos | B6: 3 | C6: Matemáticas Discretas | D6: 1 | E6: =B6-D6 -> 2 | F6: =IF(D6<B6,"Sí","NO - revisar") -> Sí
A7: Paradigmas de Programación | B7: 3 | C7: Algoritmos y Estructuras de Datos | D7: 2 | E7: =B7-D7 -> 1 | F7: =IF(D7<B7,"Sí","NO - revisar") -> Sí
A8: Ecuaciones Diferenciales | B8: 3 | C8: Cálculo Multivariable | D8: 2 | E8: =B8-D8 -> 1 | F8: =IF(D8<B8,"Sí","NO - revisar") -> Sí
A9: Bases de Datos | B9: 3 | C9: Algoritmos y Estructuras de Datos | D9: 2 | E9: =B9-D9 -> 1 | F9: =IF(D9<B9,"Sí","NO - revisar") -> Sí
A10: Diseño de Sistemas Digitales | B10: 3 | C10: Fundamentos de Diseño Digital | D10: 2 | E10: =B10-D10 -> 1 | F10: =IF(D10<B10,"Sí","NO - revisar") -> Sí
A11: Fundamentos de Inteligencia Artificial | B11: 4 | C11: Paradigmas de Programación | D11: 3 | E11: =B11-D11 -> 1 | F11: =IF(D11<B11,"Sí","NO - revisar") -> Sí
A12: Fundamentos de Inteligencia Artificial | B12: 4 | C12: Matemáticas Discretas | D12: 1 | E12: =B12-D12 -> 3 | F12: =IF(D12<B12,"Sí","NO - revisar") -> Sí
A13: Probabilidad y Estadística | B13: 4 | C13: Cálculo Multivariable | D13: 2 | E13: =B13-D13 -> 2 | F13: =IF(D13<B13,"Sí","NO - revisar") -> Sí
... A45: Desarrollo de Habilidades Sociales para la Alta Dirección | B45: 8 | C45: Liderazgo Personal | D45: 3 | E45: =B45-D45 -> 5 | F45: =IF(D45<B45,"Sí","NO - revisar") -> Sí

Sheet Regla de desfase
A1: Regla de desfase
A2: Si tienes sin aprobar una materia del semestre X, no puedes cursar ninguna materia con más de N semestres de diferencia (semestre mayor a X + N).
A4: N (máximo de semestres de diferencia) | B4: 2 | C4: ← celda editable; equivale a max_desfase/1 en conocimiento.pl (valor dado por el usuario: 2)
A5: Semestres del plan | B5: =MAX(Dependencias!A2:A46) -> 8
A7: Semestre de tu materia pendiente más atrasada (X) | B7: Semestre máximo que puedes cursar | C7: Materias del plan fuera de alcance (semestre superior al máximo)
A8: 1 | B8: =MIN($B$5,A8+$B$4) -> 3 | C8: =COUNTIF(Dependencias!$A$2:$A$46,">"&B8) -> 27
A9: 2 | B9: =MIN($B$5,A9+$B$4) -> 4 | C9: =COUNTIF(Dependencias!$A$2:$A$46,">"&B9) -> 21
A10: 3 | B10: =MIN($B$5,A10+$B$4) -> 5 | C10: =COUNTIF(Dependencias!$A$2:$A$46,">"&B10) -> 15
A11: 4 | B11: =MIN($B$5,A11+$B$4) -> 6 | C11: =COUNTIF(Dependencias!$A$2:$A$46,">"&B11) -> 9
A12: 5 | B12: =MIN($B$5,A12+$B$4) -> 7 | C12: =COUNTIF(Dependencias!$A$2:$A$46,">"&B12) -> 4
A13: 6 | B13: =MIN($B$5,A13+$B$4) -> 8 | C13: =COUNTIF(Dependencias!$A$2:$A$46,">"&B13) -> 0
A14: 7 | B14: =MIN($B$5,A14+$B$4) -> 8 | C14: =COUNTIF(Dependencias!$A$2:$A$46,">"&B14) -> 0
A15: 8 | B15: =MIN($B$5,A15+$B$4) -> 8 | C15: =COUNTIF(Dependencias!$A$2:$A$46,">"&B15) -> 0
A17: Columna C: cuántas materias del plan quedan fuera de alcance según la hoja Dependencias.
A19: Cómo se aplica en el sistema
A20: • disponibles: se excluyen las materias de semestre mayor a (semestre más atrasado pendiente + N).
A21: • bloqueadas: en "faltantes" aparecen los prerrequisitos pendientes y las materias atrasadas que causan el bloqueo.
A22: • ruta: incluye las materias atrasadas que hay que regularizar antes de llegar a la meta.
A23: • La regla se evalúa sobre TODO el catálogo (cualquier materia sin aprobar cuenta como "atrasada").

Sheet Notas
A1: Notas y supuestos
A3: Fuente del catálogo: mapa curricular "Ingeniería en Inteligencia Artificial 2020" (ESCOM-IPN).
A4: Los prerrequisitos son una PROPUESTA hecha con IA (dependencias académicas naturales); el mapa no indica seriación oficial.
A5: Optativas A–D se modelan con prerrequisito Fundamentos de Inteligencia Artificial (supuesto).
A6: Trabajo Terminal I: requiere Ingeniería de Software para Sistemas Inteligentes y Metodología de la Investigación (supuesto).
A7: Generado desde prolog/conocimiento.pl; si cambia la seriación en Prolog, actualiza esta hoja (o regenera).
